Workbook

Sheet Sales_Offline
A1: Tanggal | B1: StoreID | C1: ProductID | D1: Qty | E1: HargaJual_IDR | F1: TotalRevenue_Offline
A2: 45842 | B2: S03 | C2: P002 | D2: 4 | E2: =_xll.XLOOKUP(B2&C2,[1]PriceList!$D:$D,[1]PriceList!$C:$C,0) -> 169224 | F2: =D2*E2 -> 676896
A3: 45892 | B3: S02 | C3: P003 | D3: 2 | E3: =_xll.XLOOKUP(B3&C3,[1]PriceList!$D:$D,[1]PriceList!$C:$C,0) -> 532597 | F3: =D3*E3 -> 1065194
A4: 45859 | B4: S01 | C4: P003 | D4: 5 | E4: =_xll.XLOOKUP(B4&C4,[1]PriceList!$D:$D,[1]PriceList!$C:$C,0) -> 524199 | F4: =D4*E4 -> 2620995
A5: 45852 | B5: S04 | C5: P004 | D5: 4 | E5: =_xll.XLOOKUP(B5&C5,[1]PriceList!$D:$D,[1]PriceList!$C:$C,0) -> 338604 | F5: =D5*E5 -> 1354416
A6: 45899 | B6: S02 | C6: P006 | D6: 1 | E6: =_xll.XLOOKUP(B6&C6,[1]PriceList!$D:$D,[1]PriceList!$C:$C,0) -> 86241 | F6: =D6*E6 -> 86241
A7: 45867 | B7: S03 | C7: P002 | D7: 5 | E7: =_xll.XLOOKUP(B7&C7,[1]PriceList!$D:$D,[1]PriceList!$C:$C,0) -> 169224 | F7: =D7*E7 -> 846120
A8: 45841 | B8: S01 | C8: P003 | D8: 5 | E8: =_xll.XLOOKUP(B8&C8,[1]PriceList!$D:$D,[1]PriceList!$C:$C,0) -> 524199 | F8: =D8*E8 -> 2620995
A9: 45840 | B9: S02 | C9: P001 | D9: 3 | E9: =_xll.XLOOKUP(B9&C9,[1]PriceList!$D:$D,[1]PriceList!$C:$C,0) -> 434372 | F9: =D9*E9 -> 1303116
A10: 45873 | B10: S04 | C10: P001 | D10: 1 | E10: =_xll.XLOOKUP(B10&C10,[1]PriceList!$D:$D,[1]PriceList!$C:$C,0) -> 473548 | F10: =D10*E10 -> 473548
A11: 45898 | B11: S01 | C11: P003 | D11: 2 | E11: =_xll.XLOOKUP(B11&C11,[1]PriceList!$D:$D,[1]PriceList!$C:$C,0) -> 524199 | F11: =D11*E11 -> 1048398
A12: 45884 | B12: S01 | C12: P006 | D12: 1 | E12: =_xll.XLOOKUP(B12&C12,[1]PriceList!$D:$D,[1]PriceList!$C:$C,0) -> 110059 | F12: =D12*E12 -> 110059
A13: 45859 | B13: S04 | C13: P002 | D13: 2 | E13: =_xll.XLOOKUP(B13&C13,[1]PriceList!$D:$D,[1]PriceList!$C:$C,0) -> 207475 | F13: =D13*E13 -> 414950
... A35: 45887 | B35: S01 | C35: P003 | D35: 2 | E35: =_xll.XLOOKUP(B35&C35,[1]PriceList!$D:$D,[1]PriceList!$C:$C,0) -> 524199 | F35: =D35*E35 -> 1048398
A36: 45885 | C36: P003 | D36: 3 | E36: =_xll.XLOOKUP(B36&C36,[1]PriceList!$D:$D,[1]PriceList!$C:$C,0) -> 0 | F36: =D36*E36 -> 0
A37: 45843 | B37: S02 | C37: P999 | D37: 1 | E37: =_xll.XLOOKUP(B37&C37,[1]PriceList!$D:$D,[1]PriceList!$C:$C,0) -> 0 | F37: =D37*E37 -> 0
A38: 45854 | B38: S01 | C38: P999 | D38: 2 | E38: =_xll.XLOOKUP(B38&C38,[1]PriceList!$D:$D,[1]PriceList!$C:$C,0) -> 0 | F38: =D38*E38 -> 0
A39: 45878 | B39: S04 | C39: P004 | D39: 1 | E39: =_xll.XLOOKUP(B39&C39,[1]PriceList!$D:$D,[1]PriceList!$C:$C,0) -> 338604 | F39: =D39*E39 -> 338604
A40: 45865 | B40: S03 | C40: P001 | D40: 5 | E40: =_xll.XLOOKUP(B40&C40,[1]PriceList!$D:$D,[1]PriceList!$C:$C,0) -> 468002 | F40: =D40*E40 -> 2340010
A41: 45850 | B41: S01 | C41: P005 | D41: 1 | E41: =_xll.XLOOKUP(B41&C41,[1]PriceList!$D:$D,[1]PriceList!$C:$C,0) -> 218017 | F41: =D41*E41 -> 218017
A42: 45896 | B42: S01 | C42: P003 | D42: 1 | E42: =_xll.XLOOKUP(B42&C42,[1]PriceList!$D:$D,[1]PriceList!$C:$C,0) -> 524199 | F42: =D42*E42 -> 524199
A43: 45847 | C43: P005 | D43: 1 | E43: =_xll.XLOOKUP(B43&C43,[1]PriceList!$D:$D,[1]PriceList!$C:$C,0) -> 0 | F43: =D43*E43 -> 0
A44: 45861 | B44: S04 | C44: P999 | D44: 4 | E44: =_xll.XLOOKUP(B44&C44,[1]PriceList!$D:$D,[1]PriceList!$C:$C,0) -> 0 | F44: =D44*E44 -> 0
A45: 45846 | B45: S04 | C45: P006 | D45: 1 | E45: =_xll.XLOOKUP(B45&C45,[1]PriceList!$D:$D,[1]PriceList!$C:$C,0) -> 121595 | F45: =D45*E45 -> 121595
A46: 45881 | B46: S02 | C46: P006 | D46: 3 | E46: =_xll.XLOOKUP(B46&C46,[1]PriceList!$D:$D,[1]PriceList!$C:$C,0) -> 86241 | F46: =D46*E46 -> 258723
A47: 45897 | C47: P002 | D47: 1 | E47: =_xll.XLOOKUP(B47&C47,[1]PriceList!$D:$D,[1]PriceList!$C:$C,0) -> 0 | F47: =D47*E47 -> 0
A48: 45886 | B48: S03 | C48: P005 | D48: 5 | E48: =_xll.XLOOKUP(B48&C48,[1]PriceList!$D:$D,[1]PriceList!$C:$C,0) -> 218712 | F48: =D48*E48 -> 1093560
A49: 45844 | B49: S01 | C49: P001 | D49: 4 | E49: =_xll.XLOOKUP(B49&C49,[1]PriceList!$D:$D,[1]PriceList!$C:$C,0) -> 442673 | F49: =D49*E49 -> 1770692
A50: 45876 | B50: S03 | C50: P002 | D50: 4 | E50: =_xll.XLOOKUP(B50&C50,[1]PriceList!$D:$D,[1]PriceList!$C:$C,0) -> 169224 | F50: =D50*E50 -> 676896
A51: 45860 | B51: S04 | C51: P006 | D51: 5 | E51: =_xll.XLOOKUP(B51&C51,[1]PriceList!$D:$D,[1]PriceList!$C:$C,0) -> 121595 | F51: =D51*E51 -> 607975
A52: 45849 | B52: S04 | C52: P003 | D52: 1 | E52: =_xll.XLOOKUP(B52&C52,[1]PriceList!$D:$D,[1]PriceList!$C:$C,0) -> 533416 | F52: =D52*E52 -> 533416
A53: 45856 | B53: S04 | C53: P005 | D53: 5 | E53: =_xll.XLOOKUP(B53&C53,[1]PriceList!$D:$D,[1]PriceList!$C:$C,0) -> 239391 | F53: =D53*E53 -> 1196955
A54: 45895 | B54: S03 | C54: P004 | D54: 3 | E54: =_xll.XLOOKUP(B54&C54,[1]PriceList!$D:$D,[1]PriceList!$C:$C,0) -> 316210 | F54: =D54*E54 -> 948630
A55: 45890 | C55: P001 | D55: 3 | E55: =_xll.XLOOKUP(B55&C55,[1]PriceList!$D:$D,[1]PriceList!$C:$C,0) -> 0 | F55: =D55*E55 -> 0
A56: 45898 | B56: S04 | C56: P005 | D56: 5 | E56: =_xll.XLOOKUP(B56&C56,[1]PriceList!$D:$D,[1]PriceList!$C:$C,0) -> 239391 | F56: =D56*E56 -> 1196955
A57: 45843 | B57: S02 | C57: P002 | D57: 2 | E57: =_xll.XLOOKUP(B57&C57,[1]PriceList!$D:$D,[1]PriceList!$C:$C,0) -> 170201 | F57: =D57*E57 -> 340402
A58: 45890 | B58: S02 | C58: P002 | D58: 3 | E58: =_xll.XLOOKUP(B58&C58,[1]PriceList!$D:$D,[1]PriceList!$C:$C,0) -> 170201 | F58: =D58*E58 -> 510603
A59: 45852 | B59: S01 | C59: P006 | D59: 5 | E59: =_xll.XLOOKUP(B59&C59,[1]PriceList!$D:$D,[1]PriceList!$C:$C,0) -> 110059 | F59: =D59*E59 -> 550295
A60: 45844 | B60: S02 | C60: P005 | D60: 5 | E60: =_xll.XLOOKUP(B60&C60,[1]PriceList!$D:$D,[1]PriceList!$C:$C,0) -> 232909 | F60: =D60*E60 -> 1164545
A61: 45873 | B61: S03 | C61: P003 | D61: 3 | E61: =_xll.XLOOKUP(B61&C61,[1]PriceList!$D:$D,[1]PriceList!$C:$C,0) -> 504289 | F61: =D61*E61 -> 1512867
...

Sheet Orders_Online
A1: Tanggal | B1: OrderID | C1: CustID | D1: ProductID | E1: Qty | F1: Tier | G1: ValidTRX
A2: 22-07-2025 | B2: O1000 | C2: C02 | D2: P006 | E2: 3 | F2: =_xll.XLOOKUP(C2,[1]Customers!$A:$A,[1]Customers!$D:$D,"-") -> Silver | G2: =IF(AND(COUNTIF([1]Customers!$A:$A,C2)>0,COUNTIF([1]Products!$A:$A,D2)>0),"Valid","Invalid") -> Valid
A3: 31-07-2025 | B3: O1001 | C3: C01 | D3: P002 | E3: 3 | F3: =_xll.XLOOKUP(C3,[1]Customers!$A:$A,[1]Customers!$D:$D,"-") -> Gold | G3: =IF(AND(COUNTIF([1]Customers!$A:$A,C3)>0,COUNTIF([1]Products!$A:$A,D3)>0),"Valid","Invalid") -> Valid | I3: CustID | J3: Tier | K3: Qty | L3: Ongkir
A4: 20-07-2025 | B4: O1002 | C4: C03 | D4: P005 | E4: 1 | F4: =_xll.XLOOKUP(C4,[1]Customers!$A:$A,[1]Customers!$D:$D,"-") -> Bronze | G4: =IF(AND(COUNTIF([1]Customers!$A:$A,C4)>0,COUNTIF([1]Products!$A:$A,D4)>0),"Valid","Invalid") -> Valid | I4: C01 | J4: Gold | K4: =SUMIFS(E:E,C:C,I4,G:G,"Valid") -> 81 | L4: 15000
A5: 20-07-2025 | B5: O1003 | C5: C05 | D5: P001 | E5: 2 | F5: =_xll.XLOOKUP(C5,[1]Customers!$A:$A,[1]Customers!$D:$D,"-") -> Silver | G5: =IF(AND(COUNTIF([1]Customers!$A:$A,C5)>0,COUNTIF([1]Products!$A:$A,D5)>0),"Valid","Invalid") -> Valid | I5: C02 | J5: Silver | K5: =SUMIFS(E:E,C:C,I5,G:G,"Valid") -> 92 | L5: 20000
A6: 17-07-2025 | B6: O1004 | C6: C04 | D6: P006 | E6: 4 | F6: =_xll.XLOOKUP(C6,[1]Customers!$A:$A,[1]Customers!$D:$D,"-") -> Gold | G6: =IF(AND(COUNTIF([1]Customers!$A:$A,C6)>0,COUNTIF([1]Products!$A:$A,D6)>0),"Valid","Invalid") -> Valid | I6: C03 | J6: Bronze | K6: =SUMIFS(E:E,C:C,I6,G:G,"Valid") -> 108 | L6: 25000
A7: 19-07-2025 | B7: O1005 | C7: C99 | D7: P002 | E7: 4 | F7: =_xll.XLOOKUP(C7,[1]Customers!$A:$A,[1]Customers!$D:$D,"-") -> - | G7: =IF(AND(COUNTIF([1]Customers!$A:$A,C7)>0,COUNTIF([1]Products!$A:$A,D7)>0),"Valid","Invalid") -> Invalid | I7: C04 | J7: Gold | K7: =SUMIFS(E:E,C:C,I7,G:G,"Valid") -> 98 | L7: 22000
A8: 03-07-2025 | B8: O1006 | C8: C05 | D8: P003 | E8: 2 | F8: =_xll.XLOOKUP(C8,[1]Customers!$A:$A,[1]Customers!$D:$D,"-") -> Silver | G8: =IF(AND(COUNTIF([1]Customers!$A:$A,C8)>0,COUNTIF([1]Products!$A:$A,D8)>0),"Valid","Invalid") -> Valid | I8: C05 | J8: Silver | K8: =SUMIFS(E:E,C:C,I8,G:G,"Valid") -> 125 | L8: 24000
A9: 10-07-2025 | B9: O1007 | C9: C05 | D9: P005 | E9: 1 | F9: =_xll.XLOOKUP(C9,[1]Customers!$A:$A,[1]Customers!$D:$D,"-") -> Silver | G9: =IF(AND(COUNTIF([1]Customers!$A:$A,C9)>0,COUNTIF([1]Products!$A:$A,D9)>0),"Valid","Invalid") -> Valid
A10: 17-08-2025 | B10: O1008 | C10: C05 | D10: P002 | E10: 1 | F10: =_xll.XLOOKUP(C10,[1]Customers!$A:$A,[1]Customers!$D:$D,"-") -> Silver | G10: =IF(AND(COUNTIF([1]Customers!$A:$A,C10)>0,COUNTIF([1]Products!$A:$A,D10)>0),"Valid","Invalid") -> Valid
A11: 24-07-2025 | B11: O1009 | C11: C03 | D11: P006 | E11: 1 | F11: =_xll.XLOOKUP(C11,[1]Customers!$A:$A,[1]Customers!$D:$D,"-") -> Bronze | G11: =IF(AND(COUNTIF([1]Customers!$A:$A,C11)>0,COUNTIF([1]Products!$A:$A,D11)>0),"Valid","Invalid") -> Valid
A12: 15-07-2025 | B12: O1010 | C12: C03 | D12: P003 | E12: 3 | F12: =_xll.XLOOKUP(C12,[1]Customers!$A:$A,[1]Customers!$D:$D,"-") -> Bronze | G12: =IF(AND(COUNTIF([1]Customers!$A:$A,C12)>0,COUNTIF([1]Products!$A:$A,D12)>0),"Valid","Invalid") -> Valid
A13: 29-07-2025 | B13: O1011 | C13: C03 | D13: P006 | E13: 2 | F13: =_xll.XLOOKUP(C13,[1]Customers!$A:$A,[1]Customers!$D:$D,"-") -> Bronze | G13: =IF(AND(COUNTIF([1]Customers!$A:$A,C13)>0,COUNTIF([1]Products!$A:$A,D13)>0),"Valid","Invalid") -> Valid
A14: 14-08-2025 | B14: O1012 | C14: C03 | D14: P001 | E14: 3 | F14: =_xll.XLOOKUP(C14,[1]Customers!$A:$A,[1]Customers!$D:$D,"-") -> Bronze | G14: =IF(AND(COUNTIF([1]Customers!$A:$A,C14)>0,COUNTIF([1]Products!$A:$A,D14)>0),"Valid","Invalid") -> Valid
A15: 05-07-2025 | B15: O1013 | C15: C01 | D15: P006 | E15: 2 | F15: =_xll.XLOOKUP(C15,[1]Customers!$A:$A,[1]Customers!$D:$D,"-") -> Gold | G15: =IF(AND(COUNTIF([1]Customers!$A:$A,C15)>0,COUNTIF([1]Products!$A:$A,D15)>0),"Valid","Invalid") -> Valid
A16: 10-07-2025 | B16: O1014 | C16: C05 | D16: P005 | E16: 2 | F16: =_xll.XLOOKUP(C16,[1]Customers!$A:$A,[1]Customers!$D:$D,"-") -> Silver | G16: =IF(AND(COUNTIF([1]Customers!$A:$A,C16)>0,COUNTIF([1]Products!$A:$A,D16)>0),"Valid","Invalid") -> Valid
A17: 18-08-2025 | B17: O1015 | C17: C03 | D17: P003 | E17: 1 | F17: =_xll.XLOOKUP(C17,[1]Customers!$A:$A,[1]Customers!$D:$D,"-") -> Bronze | G17: =IF(AND(COUNTIF([1]Customers!$A:$A,C17)>0,COUNTIF([1]Products!$A:$A,D17)>0),"Valid","Invalid") -> Valid
A18: 08-08-2025 | B18: O1016 | C18: C05 | D18: P004 | E18: 2 | F18: =_xll.XLOOKUP(C18,[1]Customers!$A:$A,[1]Customers!$D:$D,"-") -> Silver | G18: =IF(AND(COUNTIF([1]Customers!$A:$A,C18)>0,COUNTIF([1]Products!$A:$A,D18)>0),"Valid","Invalid") -> Valid
A19: 28-08-2025 | B19: O1017 | C19: C03 | D19: P005 | E19: 3 | F19: =_xll.XLOOKUP(C19,[1]Customers!$A:$A,[1]Customers!$D:$D,"-") -> Bronze | G19: =IF(AND(COUNTIF([1]Customers!$A:$A,C19)>0,COUNTIF([1]Products!$A:$A,D19)>0),"Valid","Invalid") -> Valid
A20: 27-07-2025 | B20: O1018 | C20: C03 | D20: P005 | E20: 3 | F20: =_xll.XLOOKUP(C20,[1]Customers!$A:$A,[1]Customers!$D:$D,"-") -> Bronze | G20: =IF(AND(COUNTIF([1]Customers!$A:$A,C20)>0,COUNTIF([1]Products!$A:$A,D20)>0),"Valid","Invalid") -> Valid
... A221: 18-07-2025 | B221: O1219 | C221: C99 | D221: P003 | E221: 4 | F221: =_xll.XLOOKUP(C221,[1]Customers!$A:$A,[1]Customers!$D:$D,"-") -> - | G221: =IF(AND(COUNTIF([1]Customers!$A:$A,C221)>0,COUNTIF([1]Products!$A:$A,D221)>0),"Valid","Invalid") -> Invalid

Sheet Returns
A1: OrderID | B1: Alasan | C1: ProductID | D1: NamaProduk
A2: O1048 | B2: Lainnya | C2: =_xll.XLOOKUP(A2,Orders_Online!B:B,Orders_Online!D:D) -> P004 | D2: =_xll.XLOOKUP(C2,[1]Products!$A:$A,[1]Products!$B:$B) -> Webcam HD | H2: Alasan | I2: Banyak Retur
A3: O1114 | B3: Salah Kirim | C3: =_xll.XLOOKUP(A3,Orders_Online!B:B,Orders_Online!D:D) -> P001 | D3: =_xll.XLOOKUP(C3,[1]Products!$A:$A,[1]Products!$B:$B) -> Keyboard Mecha | H3: Lainnya | I3: =COUNTIF(B:B,H3) -> 4
A4: O1028 | B4: Rusak | C4: =_xll.XLOOKUP(A4,Orders_Online!B:B,Orders_Online!D:D) -> P006 | D4: =_xll.XLOOKUP(C4,[1]Products!$A:$A,[1]Products!$B:$B) -> Mousepad XXL | H4: Rusak | I4: =COUNTIF(B:B,H4) -> 3
A5: O1117 | B5: Salah Kirim | C5: =_xll.XLOOKUP(A5,Orders_Online!B:B,Orders_Online!D:D) -> P002 | D5: =_xll.XLOOKUP(C5,[1]Products!$A:$A,[1]Products!$B:$B) -> Mouse Wireless | H5: Salah Kirim | I5: =COUNTIF(B:B,H5) -> 11
A6: O1095 | B6: Tidak Puas | C6: =_xll.XLOOKUP(A6,Orders_Online!B:B,Orders_Online!D:D) -> P002 | D6: =_xll.XLOOKUP(C6,[1]Products!$A:$A,[1]Products!$B:$B) -> Mouse Wireless | H6: Tidak Puas | I6: =COUNTIF(B:B,H6) -> 6
A7: O1015 | B7: Salah Kirim | C7: =_xll.XLOOKUP(A7,Orders_Online!B:B,Orders_Online!D:D) -> P003 | D7: =_xll.XLOOKUP(C7,[1]Products!$A:$A,[1]Products!$B:$B) -> Headset Gaming
A8: O1131 | B8: Tidak Puas | C8: =_xll.XLOOKUP(A8,Orders_Online!B:B,Orders_Online!D:D) -> P004 | D8: =_xll.XLOOKUP(C8,[1]Products!$A:$A,[1]Products!$B:$B) -> Webcam HD | H8: ProductID | I8: NamaProduk | J8: Banyak Retur | K8: Alasan
A9: O1036 | B9: Salah Kirim | C9: =_xll.XLOOKUP(A9,Orders_Online!B:B,Orders_Online!D:D) -> P006 | D9: =_xll.XLOOKUP(C9,[1]Products!$A:$A,[1]Products!$B:$B) -> Mousepad XXL | K9: Rusak | L9: Salah Kirim | M9: Tidak Puas | N9: Lainnya
A10: O1054 | B10: Salah Kirim | C10: =_xll.XLOOKUP(A10,Orders_Online!B:B,Orders_Online!D:D) -> P002 | D10: =_xll.XLOOKUP(C10,[1]Products!$A:$A,[1]Products!$B:$B) -> Mouse Wireless | H10: P001 | I10: Keyboard Mecha | J10: =COUNTIF(C:C,H10) -> 6 | K10: =COUNTIFS(C:C,H10,B:B,$K$9) -> 0 | L10: =COUNTIFS(C:C,H10,B:B,$L$9) -> 3 | M10: =COUNTIFS(C:C,H10,B:B,$M$9) -> 2 | N10: =COUNTIFS(C:C,H10,B:B,$N$9) -> 1
A11: O1150 | B11: Rusak | C11: =_xll.XLOOKUP(A11,Orders_Online!B:B,Orders_Online!D:D) -> P003 | D11: =_xll.XLOOKUP(C11,[1]Products!$A:$A,[1]Products!$B:$B) -> Headset Gaming | H11: P002 | I11: Mouse Wireless | J11: =COUNTIF(C:C,H11) -> 5 | K11: =COUNTIFS(C:C,H11,B:B,$K$9) -> 0 | L11: =COUNTIFS(C:C,H11,B:B,$L$9) -> 3 | M11: =COUNTIFS(C:C,H11,B:B,$M$9) -> 1 | N11: =COUNTIFS(C:C,H11,B:B,$N$9) -> 1
A12: O1083 | B12: Tidak Puas | C12: =_xll.XLOOKUP(A12,Orders_Online!B:B,Orders_Online!D:D) -> P001 | D12: =_xll.XLOOKUP(C12,[1]Products!$A:$A,[1]Products!$B:$B) -> Keyboard Mecha | H12: P003 | I12: Headset Gaming | J12: =COUNTIF(C:C,H12) -> 5 | K12: =COUNTIFS(C:C,H12,B:B,$K$9) -> 1 | L12: =COUNTIFS(C:C,H12,B:B,$L$9) -> 2 | M12: =COUNTIFS(C:C,H12,B:B,$M$9) -> 1 | N12: =COUNTIFS(C:C,H12,B:B,$N$9) -> 1
A13: O1122 | B13: Lainnya | C13: =_xll.XLOOKUP(A13,Orders_Online!B:B,Orders_Online!D:D) -> P003 | D13: =_xll.XLOOKUP(C13,[1]Products!$A:$A,[1]Products!$B:$B) -> Headset Gaming | H13: P004 | I13: Webcam HD | J13: =COUNTIF(C:C,H13) -> 2 | K13: =COUNTIFS(C:C,H13,B:B,$K$9) -> 0 | L13: =COUNTIFS(C:C,H13,B:B,$L$9) -> 0 | M13: =COUNTIFS(C:C,H13,B:B,$M$9) -> 1 | N13: =COUNTIFS(C:C,H13,B:B,$N$9) -> 1
A14: O1176 | B14: Salah Kirim | C14: =_xll.XLOOKUP(A14,Orders_Online!B:B,Orders_Online!D:D) -> P006 | D14: =_xll.XLOOKUP(C14,[1]Products!$A:$A,[1]Products!$B:$B) -> Mousepad XXL | H14: P005 | I14: USB-C Hub | J14: =COUNTIF(C:C,H14) -> 1 | K14: =COUNTIFS(C:C,H14,B:B,$K$9) -> 0 | L14: =COUNTIFS(C:C,H14,B:B,$L$9) -> 0 | M14: =COUNTIFS(C:C,H14,B:B,$M$9) -> 1 | N14: =COUNTIFS(C:C,H14,B:B,$N$9) -> 0
A15: O1170 | B15: Salah Kirim | C15: =_xll.XLOOKUP(A15,Orders_Online!B:B,Orders_Online!D:D) -> P001 | D15: =_xll.XLOOKUP(C15,[1]Products!$A:$A,[1]Products!$B:$B) -> Keyboard Mecha | H15: P006 | I15: Mousepad XXL | J15: =COUNTIF(C:C,H15) -> 5 | K15: =COUNTIFS(C:C,H15,B:B,$K$9) -> 2 | L15: =COUNTIFS(C:C,H15,B:B,$L$9) -> 3 | M15: =COUNTIFS(C:C,H15,B:B,$M$9) -> 0 | N15: =COUNTIFS(C:C,H15,B:B,$N$9) -> 0
A16: O1102 | B16: Tidak Puas | C16: =_xll.XLOOKUP(A16,Orders_Online!B:B,Orders_Online!D:D) -> P005 | D16: =_xll.XLOOKUP(C16,[1]Products!$A:$A,[1]Products!$B:$B) -> USB-C Hub
A17: O1218 | B17: Salah Kirim | C17: =_xll.XLOOKUP(A17,Orders_Online!B:B,Orders_Online!D:D) -> P002 | D17: =_xll.XLOOKUP(C17,[1]Products!$A:$A,[1]Products!$B:$B) -> Mouse Wireless
A18: O1061 | B18: Salah Kirim | C18: =_xll.XLOOKUP(A18,Orders_Online!B:B,Orders_Online!D:D) -> P006 | D18: =_xll.XLOOKUP(C18,[1]Products!$A:$A,[1]Products!$B:$B) -> Mousepad XXL
A19: O1038 | B19: Tidak Puas | C19: =_xll.XLOOKUP(A19,Orders_Online!B:B,Orders_Online!D:D) -> P003 | D19: =_xll.XLOOKUP(C19,[1]Products!$A:$A,[1]Products!$B:$B) -> Headset Gaming
A20: O1055 | B20: Lainnya | C20: =_xll.XLOOKUP(A20,Orders_Online!B:B,Orders_Online!D:D) -> P002 | D20: =_xll.XLOOKUP(C20,[1]Products!$A:$A,[1]Products!$B:$B) -> Mouse Wireless
A21: O1193 | B21: Rusak | C21: =_xll.XLOOKUP(A21,Orders_Online!B:B,Orders_Online!D:D) -> P006 | D21: =_xll.XLOOKUP(C21,[1]Products!$A:$A,[1]Products!$B:$B) -> Mousepad XXL
A22: O1113 | B22: Salah Kirim | C22: =_xll.XLOOKUP(A22,Orders_Online!B:B,Orders_Online!D:D) -> P001 | D22: =_xll.XLOOKUP(C22,[1]Products!$A:$A,[1]Products!$B:$B) -> Keyboard Mecha
A23: O1146 | B23: Lainnya | C23: =_xll.XLOOKUP(A23,Orders_Online!B:B,Orders_Online!D:D) -> P001 | D23: =_xll.XLOOKUP(C23,[1]Products!$A:$A,[1]Products!$B:$B) -> Keyboard Mecha
A24: O1080 | B24: Salah Kirim | C24: =_xll.XLOOKUP(A24,Orders_Online!B:B,Orders_Online!D:D) -> P003 | D24: =_xll.XLOOKUP(C24,[1]Products!$A:$A,[1]Products!$B:$B) -> Headset Gaming
A25: O1070 | B25: Tidak Puas | C25: =_xll.XLOOKUP(A25,Orders_Online!B:B,Orders_Online!D:D) -> P001 | D25: =_xll.XLOOKUP(C25,[1]Products!$A:$A,[1]Products!$B:$B) -> Keyboard Mecha

Sheet Targets
A1: StoreID | B1: Bulan | C1: TargetQty | D1: TargetRevenue_IDR
A2: S01 | B2: 07-2025 | C2: 110 | D2: 22000000
A3: S02 | B3: 07-2025 | C3: 140 | D3: 28000000
A4: S03 | B4: 07-2025 | C4: 90 | D4: 18000000
A5: S04 | B5: 07-2025 | C5: 85 | D5: 16000000
